[2025-03-05T10:25:19.123+0000] {scheduler_job_runner.py:781} ERROR - Executor reports task instance <TaskInstance: ingestao_cliente.generate_csv scheduled__2025-03-04T00:00:00+00:00 [queued]> finished (failed) although the task says it's queued. (Info: None) Was the task killed externally?
