[2025-03-05T10:26:21.822+0000] {taskinstance.py:1979} INFO - Dependencies all met for dep_context=non-requeueable deps ti=<TaskInstance: ingestao_cliente.generate_csv manual__2025-03-05T10:26:20.949992+00:00 [queued]>
[2025-03-05T10:26:21.833+0000] {taskinstance.py:1979} INFO - Dependencies all met for dep_context=requeueable deps ti=<TaskInstance: ingestao_cliente.generate_csv manual__2025-03-05T10:26:20.949992+00:00 [queued]>
[2025-03-05T10:26:21.833+0000] {taskinstance.py:2193} INFO - Starting attempt 1 of 2
[2025-03-05T10:26:21.845+0000] {taskinstance.py:2217} INFO - Executing <Task(BashOperator): generate_csv> on 2025-03-05 10:26:20.949992+00:00
[2025-03-05T10:26:21.847+0000] {standard_task_runner.py:60} INFO - Started process 209 to run task
[2025-03-05T10:26:21.850+0000] {standard_task_runner.py:87} INFO - Running: ['***', 'tasks', 'run', 'ingestao_cliente', 'generate_csv', 'manual__2025-03-05T10:26:20.949992+00:00', '--job-id', '5', '--raw', '--subdir', 'DAGS_FOLDER/ingestao_cliente.py', '--cfg-path', '/tmp/tmpo4t6qvof']
[2025-03-05T10:26:21.851+0000] {standard_task_runner.py:88} INFO - Job 5: Subtask generate_csv
[2025-03-05T10:26:21.900+0000] {task_command.py:423} INFO - Running <TaskInstance: ingestao_cliente.generate_csv manual__2025-03-05T10:26:20.949992+00:00 [running]> on host 3bbc697e2df9
[2025-03-05T10:26:21.975+0000] {taskinstance.py:2513} INFO - Exporting env vars: AIRFLOW_CTX_DAG_OWNER='***' AIRFLOW_CTX_DAG_ID='ingestao_cliente' AIRFLOW_CTX_TASK_ID='generate_csv' AIRFLOW_CTX_EXECUTION_DATE='2025-03-05T10:26:20.949992+00:00' AIRFLOW_CTX_TRY_NUMBER='1' AIRFLOW_CTX_DAG_RUN_ID='manual__2025-03-05T10:26:20.949992+00:00'
[2025-03-05T10:26:21.976+0000] {subprocess.py:63} INFO - Tmp dir root location: /tmp
[2025-03-05T10:26:21.977+0000] {subprocess.py:75} INFO - Running command: ['/usr/bin/bash', '-c', 'python ingestion/generate_csv.py']
[2025-03-05T10:26:21.981+0000] {subprocess.py:86} INFO - Output:
[2025-03-05T10:26:21.997+0000] {subprocess.py:93} INFO - python: can't open file 'ingestion/generate_csv.py': [Errno 2] No such file or directory
[2025-03-05T10:26:21.999+0000] {subprocess.py:97} INFO - Command exited with return code 2
[2025-03-05T10:26:22.009+0000] {taskinstance.py:2731} ERROR - Task failed with exception
Traceback (most recent call last):
  File "/home/airflow/.local/lib/python3.8/site-packages/airflow/models/taskinstance.py", line 444, in _execute_task
    result = _execute_callable(context=context, **execute_callable_kwargs)
  File "/home/airflow/.local/lib/python3.8/site-packages/airflow/models/taskinstance.py", line 414, in _execute_callable
    return execute_callable(context=context, **execute_callable_kwargs)
  File "/home/airflow/.local/lib/python3.8/site-packages/airflow/operators/bash.py", line 212, in execute
    raise AirflowException(
airflow.exceptions.AirflowException: Bash command failed. The command returned a non-zero exit code 2.
[2025-03-05T10:26:22.011+0000] {taskinstance.py:1149} INFO - Marking task as UP_FOR_RETRY. dag_id=ingestao_cliente, task_id=generate_csv, execution_date=20250305T102620, start_date=20250305T102621, end_date=20250305T102622
[2025-03-05T10:26:22.021+0000] {standard_task_runner.py:107} ERROR - Failed to execute job 5 for task generate_csv (Bash command failed. The command returned a non-zero exit code 2.; 209)
[2025-03-05T10:26:22.028+0000] {local_task_job_runner.py:234} INFO - Task exited with return code 1
[2025-03-05T10:26:22.046+0000] {taskinstance.py:3312} INFO - 0 downstream tasks scheduled from follow-on schedule check
